/home/nr4325/miniconda3/envs/pose4/lib/python3.8/site-packages/mmengine/utils/dl_utils/setup_env.py:56: UserWarning: Setting MKL_NUM_THREADS environment variable for each process to be 1 in default, to avoid your system being overloaded, please further tune the variable for optimal performance in your application as needed.
  warnings.warn(
/home/nr4325/miniconda3/envs/pose4/lib/python3.8/site-packages/mmengine/utils/dl_utils/setup_env.py:56: UserWarning: Setting MKL_NUM_THREADS environment variable for each process to be 1 in default, to avoid your system being overloaded, please further tune the variable for optimal performance in your application as needed.
  warnings.warn(
/home/nr4325/miniconda3/envs/pose4/lib/python3.8/site-packages/mmengine/utils/dl_utils/setup_env.py:56: UserWarning: Setting MKL_NUM_THREADS environment variable for each process to be 1 in default, to avoid your system being overloaded, please further tune the variable for optimal performance in your application as needed.
  warnings.warn(
/home/nr4325/miniconda3/envs/pose4/lib/python3.8/site-packages/mmengine/utils/dl_utils/setup_env.py:56: UserWarning: Setting MKL_NUM_THREADS environment variable for each process to be 1 in default, to avoid your system being overloaded, please further tune the variable for optimal performance in your application as needed.
  warnings.warn(
Traceback (most recent call last):
  File "tools/train.py", line 161, in <module>
    main()
  File "tools/train.py", line 157, in main
    runner.train()
  File "/home/nr4325/miniconda3/envs/pose4/lib/python3.8/site-packages/mmengine/runner/runner.py", line 1723, in train
    self._init_model_weights()
  File "/home/nr4325/miniconda3/envs/pose4/lib/python3.8/site-packages/mmengine/runner/runner.py", line 906, in _init_model_weights
    model.init_weights()
  File "/home/nr4325/miniconda3/envs/pose4/lib/python3.8/site-packages/mmengine/model/base_module.py", line 136, in init_weights
    m.init_weights()
  File "/home/nr4325/Desktop/Pose4/mmpose/mmpose/models/backbones/wt_swinv2.py", line 820, in init_weights
    super(wtSwinV2, self).init_weights()
  File "/home/nr4325/miniconda3/envs/pose4/lib/python3.8/site-packages/mmengine/model/base_module.py", line 144, in init_weights
    initialize(self, pretrained_cfg)
  File "/home/nr4325/miniconda3/envs/pose4/lib/python3.8/site-packages/mmengine/model/weight_init.py", line 610, in initialize
    _initialize(module, cp_cfg)
  File "/home/nr4325/miniconda3/envs/pose4/lib/python3.8/site-packages/mmengine/model/weight_init.py", line 518, in _initialize
    func(module)
  File "/home/nr4325/miniconda3/envs/pose4/lib/python3.8/site-packages/mmengine/model/weight_init.py", line 490, in __call__
    load_checkpoint(
  File "/home/nr4325/miniconda3/envs/pose4/lib/python3.8/site-packages/mmengine/runner/checkpoint.py", line 636, in load_checkpoint
    checkpoint = _load_checkpoint(filename, map_location, logger)
  File "/home/nr4325/miniconda3/envs/pose4/lib/python3.8/site-packages/mmengine/runner/checkpoint.py", line 548, in _load_checkpoint
    return CheckpointLoader.load_checkpoint(filename, map_location, logger)
  File "/home/nr4325/miniconda3/envs/pose4/lib/python3.8/site-packages/mmengine/runner/checkpoint.py", line 330, in load_checkpoint
    return checkpoint_loader(filename, map_location)
  File "/home/nr4325/miniconda3/envs/pose4/lib/python3.8/site-packages/mmengine/runner/checkpoint.py", line 346, in load_from_local
    raise FileNotFoundError(f'{filename} can not be found.')
FileNotFoundError: /home/nr4325/Desktop/Pose4/mmpose/ImageNet_pretrained_model/resnet152_swinv2_b.pth can not be found.
Traceback (most recent call last):
  File "tools/train.py", line 161, in <module>
    main()
  File "tools/train.py", line 157, in main
    runner.train()
  File "/home/nr4325/miniconda3/envs/pose4/lib/python3.8/site-packages/mmengine/runner/runner.py", line 1723, in train
    self._init_model_weights()
  File "/home/nr4325/miniconda3/envs/pose4/lib/python3.8/site-packages/mmengine/runner/runner.py", line 906, in _init_model_weights
    model.init_weights()
  File "/home/nr4325/miniconda3/envs/pose4/lib/python3.8/site-packages/mmengine/model/base_module.py", line 136, in init_weights
    m.init_weights()
  File "/home/nr4325/Desktop/Pose4/mmpose/mmpose/models/backbones/wt_swinv2.py", line 820, in init_weights
    super(wtSwinV2, self).init_weights()
  File "/home/nr4325/miniconda3/envs/pose4/lib/python3.8/site-packages/mmengine/model/base_module.py", line 144, in init_weights
    initialize(self, pretrained_cfg)
  File "/home/nr4325/miniconda3/envs/pose4/lib/python3.8/site-packages/mmengine/model/weight_init.py", line 610, in initialize
    _initialize(module, cp_cfg)
  File "/home/nr4325/miniconda3/envs/pose4/lib/python3.8/site-packages/mmengine/model/weight_init.py", line 518, in _initialize
    func(module)
  File "/home/nr4325/miniconda3/envs/pose4/lib/python3.8/site-packages/mmengine/model/weight_init.py", line 490, in __call__
    load_checkpoint(
  File "/home/nr4325/miniconda3/envs/pose4/lib/python3.8/site-packages/mmengine/runner/checkpoint.py", line 636, in load_checkpoint
    checkpoint = _load_checkpoint(filename, map_location, logger)
  File "/home/nr4325/miniconda3/envs/pose4/lib/python3.8/site-packages/mmengine/runner/checkpoint.py", line 548, in _load_checkpoint
    return CheckpointLoader.load_checkpoint(filename, map_location, logger)
  File "/home/nr4325/miniconda3/envs/pose4/lib/python3.8/site-packages/mmengine/runner/checkpoint.py", line 330, in load_checkpoint
    return checkpoint_loader(filename, map_location)
  File "/home/nr4325/miniconda3/envs/pose4/lib/python3.8/site-packages/mmengine/runner/checkpoint.py", line 346, in load_from_local
    raise FileNotFoundError(f'{filename} can not be found.')
FileNotFoundError: /home/nr4325/Desktop/Pose4/mmpose/ImageNet_pretrained_model/resnet152_swinv2_b.pth can not be found.
Traceback (most recent call last):
  File "tools/train.py", line 161, in <module>
    main()
  File "tools/train.py", line 157, in main
    runner.train()
  File "/home/nr4325/miniconda3/envs/pose4/lib/python3.8/site-packages/mmengine/runner/runner.py", line 1723, in train
    self._init_model_weights()
  File "/home/nr4325/miniconda3/envs/pose4/lib/python3.8/site-packages/mmengine/runner/runner.py", line 906, in _init_model_weights
    model.init_weights()
  File "/home/nr4325/miniconda3/envs/pose4/lib/python3.8/site-packages/mmengine/model/base_module.py", line 136, in init_weights
    m.init_weights()
  File "/home/nr4325/Desktop/Pose4/mmpose/mmpose/models/backbones/wt_swinv2.py", line 820, in init_weights
    super(wtSwinV2, self).init_weights()
  File "/home/nr4325/miniconda3/envs/pose4/lib/python3.8/site-packages/mmengine/model/base_module.py", line 144, in init_weights
    initialize(self, pretrained_cfg)
  File "/home/nr4325/miniconda3/envs/pose4/lib/python3.8/site-packages/mmengine/model/weight_init.py", line 610, in initialize
    _initialize(module, cp_cfg)
  File "/home/nr4325/miniconda3/envs/pose4/lib/python3.8/site-packages/mmengine/model/weight_init.py", line 518, in _initialize
    func(module)
  File "/home/nr4325/miniconda3/envs/pose4/lib/python3.8/site-packages/mmengine/model/weight_init.py", line 490, in __call__
    load_checkpoint(
  File "/home/nr4325/miniconda3/envs/pose4/lib/python3.8/site-packages/mmengine/runner/checkpoint.py", line 636, in load_checkpoint
    checkpoint = _load_checkpoint(filename, map_location, logger)
  File "/home/nr4325/miniconda3/envs/pose4/lib/python3.8/site-packages/mmengine/runner/checkpoint.py", line 548, in _load_checkpoint
    return CheckpointLoader.load_checkpoint(filename, map_location, logger)
  File "/home/nr4325/miniconda3/envs/pose4/lib/python3.8/site-packages/mmengine/runner/checkpoint.py", line 330, in load_checkpoint
    return checkpoint_loader(filename, map_location)
  File "/home/nr4325/miniconda3/envs/pose4/lib/python3.8/site-packages/mmengine/runner/checkpoint.py", line 346, in load_from_local
    raise FileNotFoundError(f'{filename} can not be found.')
FileNotFoundError: /home/nr4325/Desktop/Pose4/mmpose/ImageNet_pretrained_model/resnet152_swinv2_b.pth can not be found.
/home/nr4325/miniconda3/envs/pose4/lib/python3.8/site-packages/torch/distributed/launch.py:178: FutureWarning: The module torch.distributed.launch is deprecated
and will be removed in future. Use torchrun.
Note that --use_env is set by default in torchrun.
If your script expects `--local_rank` argument to be set, please
change it to read from `os.environ['LOCAL_RANK']` instead. See 
https://pytorch.org/docs/stable/distributed.html#launch-utility for 
further instructions

  warnings.warn(
WARNING:torch.distributed.elastic.multiprocessing.api:Sending process 1189 closing signal SIGTERM
WARNING:torch.distributed.elastic.multiprocessing.api:Sending process 1190 closing signal SIGTERM
WARNING:torch.distributed.elastic.multiprocessing.api:Sending process 1191 closing signal SIGTERM
ERROR:torch.distributed.elastic.multiprocessing.api:failed (exitcode: 1) local_rank: 0 (pid: 1188) of binary: /home/nr4325/miniconda3/envs/pose4/bin/python
Traceback (most recent call last):
  File "/home/nr4325/miniconda3/envs/pose4/lib/python3.8/runpy.py", line 194, in _run_module_as_main
    return _run_code(code, main_globals, None,
  File "/home/nr4325/miniconda3/envs/pose4/lib/python3.8/runpy.py", line 87, in _run_code
    exec(code, run_globals)
  File "/home/nr4325/miniconda3/envs/pose4/lib/python3.8/site-packages/torch/distributed/launch.py", line 193, in <module>
    main()
  File "/home/nr4325/miniconda3/envs/pose4/lib/python3.8/site-packages/torch/distributed/launch.py", line 189, in main
    launch(args)
  File "/home/nr4325/miniconda3/envs/pose4/lib/python3.8/site-packages/torch/distributed/launch.py", line 174, in launch
    run(args)
  File "/home/nr4325/miniconda3/envs/pose4/lib/python3.8/site-packages/torch/distributed/run.py", line 715, in run
    elastic_launch(
  File "/home/nr4325/miniconda3/envs/pose4/lib/python3.8/site-packages/torch/distributed/launcher/api.py", line 131, in __call__
    return launch_agent(self._config, self._entrypoint, list(args))
  File "/home/nr4325/miniconda3/envs/pose4/lib/python3.8/site-packages/torch/distributed/launcher/api.py", line 245, in launch_agent
    raise ChildFailedError(
torch.distributed.elastic.multiprocessing.errors.ChildFailedError: 
============================================================
tools/train.py FAILED
------------------------------------------------------------
Failures:
  <NO_OTHER_FAILURES>
------------------------------------------------------------
Root Cause (first observed failure):
[0]:
  time      : 2023-09-23_03:00:22
  host      : skl-a-64.rc.rit.edu
  rank      : 0 (local_rank: 0)
  exitcode  : 1 (pid: 1188)
  error_file: <N/A>
  traceback : To enable traceback see: https://pytorch.org/docs/stable/elastic/errors.html
============================================================
