/home/nr4325/miniconda3/envs/pose4/lib/python3.8/site-packages/mmengine/utils/dl_utils/setup_env.py:56: UserWarning: Setting MKL_NUM_THREADS environment variable for each process to be 1 in default, to avoid your system being overloaded, please further tune the variable for optimal performance in your application as needed.
  warnings.warn(
/home/nr4325/miniconda3/envs/pose4/lib/python3.8/site-packages/mmengine/utils/dl_utils/setup_env.py:56: UserWarning: Setting MKL_NUM_THREADS environment variable for each process to be 1 in default, to avoid your system being overloaded, please further tune the variable for optimal performance in your application as needed.
  warnings.warn(
/home/nr4325/miniconda3/envs/pose4/lib/python3.8/site-packages/mmengine/utils/dl_utils/setup_env.py:56: UserWarning: Setting MKL_NUM_THREADS environment variable for each process to be 1 in default, to avoid your system being overloaded, please further tune the variable for optimal performance in your application as needed.
  warnings.warn(
/home/nr4325/miniconda3/envs/pose4/lib/python3.8/site-packages/mmengine/utils/dl_utils/setup_env.py:56: UserWarning: Setting MKL_NUM_THREADS environment variable for each process to be 1 in default, to avoid your system being overloaded, please further tune the variable for optimal performance in your application as needed.
  warnings.warn(
Traceback (most recent call last):
Traceback (most recent call last):
  File "tools/train.py", line 162, in <module>
Traceback (most recent call last):
  File "tools/train.py", line 162, in <module>
  File "tools/train.py", line 162, in <module>
Traceback (most recent call last):
  File "tools/train.py", line 162, in <module>
    main()
  File "tools/train.py", line 158, in main
    runner.train()
  File "/home/nr4325/miniconda3/envs/pose4/lib/python3.8/site-packages/mmengine/runner/runner.py", line 1745, in train
            main()main()main()


  File "tools/train.py", line 158, in main
  File "tools/train.py", line 158, in main
  File "tools/train.py", line 158, in main
        runner.train()    runner.train()
runner.train()

  File "/home/nr4325/miniconda3/envs/pose4/lib/python3.8/site-packages/mmengine/runner/runner.py", line 1745, in train
  File "/home/nr4325/miniconda3/envs/pose4/lib/python3.8/site-packages/mmengine/runner/runner.py", line 1745, in train
  File "/home/nr4325/miniconda3/envs/pose4/lib/python3.8/site-packages/mmengine/runner/runner.py", line 1745, in train
    model = self.train_loop.run()  # type: ignore
  File "/home/nr4325/miniconda3/envs/pose4/lib/python3.8/site-packages/mmengine/runner/loops.py", line 102, in run
            model = self.train_loop.run()  # type: ignoremodel = self.train_loop.run()  # type: ignoremodel = self.train_loop.run()  # type: ignore


  File "/home/nr4325/miniconda3/envs/pose4/lib/python3.8/site-packages/mmengine/runner/loops.py", line 102, in run
  File "/home/nr4325/miniconda3/envs/pose4/lib/python3.8/site-packages/mmengine/runner/loops.py", line 102, in run
  File "/home/nr4325/miniconda3/envs/pose4/lib/python3.8/site-packages/mmengine/runner/loops.py", line 102, in run
    self.runner.val_loop.run()
  File "/home/nr4325/miniconda3/envs/pose4/lib/python3.8/site-packages/mmengine/runner/loops.py", line 362, in run
            self.runner.val_loop.run()self.runner.val_loop.run()self.runner.val_loop.run()


  File "/home/nr4325/miniconda3/envs/pose4/lib/python3.8/site-packages/mmengine/runner/loops.py", line 362, in run
      File "/home/nr4325/miniconda3/envs/pose4/lib/python3.8/site-packages/mmengine/runner/loops.py", line 362, in run
  File "/home/nr4325/miniconda3/envs/pose4/lib/python3.8/site-packages/mmengine/runner/loops.py", line 362, in run
for idx, data_batch in enumerate(self.dataloader):
  File "/home/nr4325/miniconda3/envs/pose4/lib/python3.8/site-packages/torch/utils/data/dataloader.py", line 530, in __next__
    for idx, data_batch in enumerate(self.dataloader):
  File "/home/nr4325/miniconda3/envs/pose4/lib/python3.8/site-packages/torch/utils/data/dataloader.py", line 530, in __next__
    for idx, data_batch in enumerate(self.dataloader):    
for idx, data_batch in enumerate(self.dataloader):  File "/home/nr4325/miniconda3/envs/pose4/lib/python3.8/site-packages/torch/utils/data/dataloader.py", line 530, in __next__

  File "/home/nr4325/miniconda3/envs/pose4/lib/python3.8/site-packages/torch/utils/data/dataloader.py", line 530, in __next__
    data = self._next_data()
  File "/home/nr4325/miniconda3/envs/pose4/lib/python3.8/site-packages/torch/utils/data/dataloader.py", line 1224, in _next_data
            data = self._next_data()data = self._next_data()data = self._next_data()


  File "/home/nr4325/miniconda3/envs/pose4/lib/python3.8/site-packages/torch/utils/data/dataloader.py", line 1224, in _next_data
  File "/home/nr4325/miniconda3/envs/pose4/lib/python3.8/site-packages/torch/utils/data/dataloader.py", line 1224, in _next_data
  File "/home/nr4325/miniconda3/envs/pose4/lib/python3.8/site-packages/torch/utils/data/dataloader.py", line 1224, in _next_data
    return self._process_data(data)
  File "/home/nr4325/miniconda3/envs/pose4/lib/python3.8/site-packages/torch/utils/data/dataloader.py", line 1250, in _process_data
        return self._process_data(data)    return self._process_data(data)
return self._process_data(data)
  File "/home/nr4325/miniconda3/envs/pose4/lib/python3.8/site-packages/torch/utils/data/dataloader.py", line 1250, in _process_data
  File "/home/nr4325/miniconda3/envs/pose4/lib/python3.8/site-packages/torch/utils/data/dataloader.py", line 1250, in _process_data

  File "/home/nr4325/miniconda3/envs/pose4/lib/python3.8/site-packages/torch/utils/data/dataloader.py", line 1250, in _process_data
    data.reraise()
  File "/home/nr4325/miniconda3/envs/pose4/lib/python3.8/site-packages/torch/_utils.py", line 457, in reraise
            data.reraise()data.reraise()data.reraise()


  File "/home/nr4325/miniconda3/envs/pose4/lib/python3.8/site-packages/torch/_utils.py", line 457, in reraise
  File "/home/nr4325/miniconda3/envs/pose4/lib/python3.8/site-packages/torch/_utils.py", line 457, in reraise
  File "/home/nr4325/miniconda3/envs/pose4/lib/python3.8/site-packages/torch/_utils.py", line 457, in reraise
    raise exception
        FileNotFoundError    raise exceptionraise exception: raise exception

Caught FileNotFoundError in DataLoader worker process 1.
Original Traceback (most recent call last):
  File "/home/nr4325/miniconda3/envs/pose4/lib/python3.8/site-packages/torch/utils/data/_utils/worker.py", line 287, in _worker_loop
    data = fetcher.fetch(index)
  File "/home/nr4325/miniconda3/envs/pose4/lib/python3.8/site-packages/torch/utils/data/_utils/fetch.py", line 49, in fetch
    data = [self.dataset[idx] for idx in possibly_batched_index]
  File "/home/nr4325/miniconda3/envs/pose4/lib/python3.8/site-packages/torch/utils/data/_utils/fetch.py", line 49, in <listcomp>
    data = [self.dataset[idx] for idx in possibly_batched_index]
  File "/home/nr4325/miniconda3/envs/pose4/lib/python3.8/site-packages/mmengine/dataset/base_dataset.py", line 401, in __getitem__
    data = self.prepare_data(idx)
  File "/home/nr4325/miniconda3/envs/pose4/lib/python3.8/site-packages/mmengine/dataset/base_dataset.py", line 113, in wrapper
    return old_func(obj, *args, **kwargs)
  File "/home/nr4325/Desktop/Pose4/mmpose/mmpose/datasets/datasets/base/base_coco_style_dataset.py", line 150, in prepare_data
    return self.pipeline(data_info)
  File "/home/nr4325/miniconda3/envs/pose4/lib/python3.8/site-packages/mmengine/dataset/base_dataset.py", line 58, in __call__
    data = t(data)
  File "/home/nr4325/miniconda3/envs/pose4/lib/python3.8/site-packages/mmcv/transforms/base.py", line 12, in __call__
    return self.transform(results)
  File "/home/nr4325/Desktop/Pose4/mmpose/mmpose/datasets/transforms/loading.py", line 54, in transform
    results = super().transform(results)
  File "/home/nr4325/miniconda3/envs/pose4/lib/python3.8/site-packages/mmcv/transforms/loading.py", line 107, in transform
    raise e
  File "/home/nr4325/miniconda3/envs/pose4/lib/python3.8/site-packages/mmcv/transforms/loading.py", line 99, in transform
    img_bytes = fileio.get(
  File "/home/nr4325/miniconda3/envs/pose4/lib/python3.8/site-packages/mmengine/fileio/io.py", line 181, in get
    return backend.get(filepath)
  File "/home/nr4325/miniconda3/envs/pose4/lib/python3.8/site-packages/mmengine/fileio/backends/local_backend.py", line 33, in get
    with open(filepath, 'rb') as f:
FileNotFoundError: [Errno 2] No such file or directory: 'data/coco/val2017/000000138639.jpg'


FileNotFoundErrorFileNotFoundError: : Caught FileNotFoundError in DataLoader worker process 1.
Original Traceback (most recent call last):
  File "/home/nr4325/miniconda3/envs/pose4/lib/python3.8/site-packages/torch/utils/data/_utils/worker.py", line 287, in _worker_loop
    data = fetcher.fetch(index)
  File "/home/nr4325/miniconda3/envs/pose4/lib/python3.8/site-packages/torch/utils/data/_utils/fetch.py", line 49, in fetch
    data = [self.dataset[idx] for idx in possibly_batched_index]
  File "/home/nr4325/miniconda3/envs/pose4/lib/python3.8/site-packages/torch/utils/data/_utils/fetch.py", line 49, in <listcomp>
    data = [self.dataset[idx] for idx in possibly_batched_index]
  File "/home/nr4325/miniconda3/envs/pose4/lib/python3.8/site-packages/mmengine/dataset/base_dataset.py", line 401, in __getitem__
    data = self.prepare_data(idx)
  File "/home/nr4325/miniconda3/envs/pose4/lib/python3.8/site-packages/mmengine/dataset/base_dataset.py", line 113, in wrapper
    return old_func(obj, *args, **kwargs)
  File "/home/nr4325/Desktop/Pose4/mmpose/mmpose/datasets/datasets/base/base_coco_style_dataset.py", line 150, in prepare_data
    return self.pipeline(data_info)
  File "/home/nr4325/miniconda3/envs/pose4/lib/python3.8/site-packages/mmengine/dataset/base_dataset.py", line 58, in __call__
    data = t(data)
  File "/home/nr4325/miniconda3/envs/pose4/lib/python3.8/site-packages/mmcv/transforms/base.py", line 12, in __call__
    return self.transform(results)
  File "/home/nr4325/Desktop/Pose4/mmpose/mmpose/datasets/transforms/loading.py", line 54, in transform
    results = super().transform(results)
  File "/home/nr4325/miniconda3/envs/pose4/lib/python3.8/site-packages/mmcv/transforms/loading.py", line 107, in transform
    raise e
  File "/home/nr4325/miniconda3/envs/pose4/lib/python3.8/site-packages/mmcv/transforms/loading.py", line 99, in transform
    img_bytes = fileio.get(
  File "/home/nr4325/miniconda3/envs/pose4/lib/python3.8/site-packages/mmengine/fileio/io.py", line 181, in get
    return backend.get(filepath)
  File "/home/nr4325/miniconda3/envs/pose4/lib/python3.8/site-packages/mmengine/fileio/backends/local_backend.py", line 33, in get
    with open(filepath, 'rb') as f:
FileNotFoundError: [Errno 2] No such file or directory: 'data/coco/val2017/000000138639.jpg'
FileNotFoundErrorCaught FileNotFoundError in DataLoader worker process 1.
Original Traceback (most recent call last):
  File "/home/nr4325/miniconda3/envs/pose4/lib/python3.8/site-packages/torch/utils/data/_utils/worker.py", line 287, in _worker_loop
    data = fetcher.fetch(index)
  File "/home/nr4325/miniconda3/envs/pose4/lib/python3.8/site-packages/torch/utils/data/_utils/fetch.py", line 49, in fetch
    data = [self.dataset[idx] for idx in possibly_batched_index]
  File "/home/nr4325/miniconda3/envs/pose4/lib/python3.8/site-packages/torch/utils/data/_utils/fetch.py", line 49, in <listcomp>
    data = [self.dataset[idx] for idx in possibly_batched_index]
  File "/home/nr4325/miniconda3/envs/pose4/lib/python3.8/site-packages/mmengine/dataset/base_dataset.py", line 401, in __getitem__
    data = self.prepare_data(idx)
  File "/home/nr4325/miniconda3/envs/pose4/lib/python3.8/site-packages/mmengine/dataset/base_dataset.py", line 113, in wrapper
    return old_func(obj, *args, **kwargs)
  File "/home/nr4325/Desktop/Pose4/mmpose/mmpose/datasets/datasets/base/base_coco_style_dataset.py", line 150, in prepare_data
    return self.pipeline(data_info)
  File "/home/nr4325/miniconda3/envs/pose4/lib/python3.8/site-packages/mmengine/dataset/base_dataset.py", line 58, in __call__
    data = t(data)
  File "/home/nr4325/miniconda3/envs/pose4/lib/python3.8/site-packages/mmcv/transforms/base.py", line 12, in __call__
    return self.transform(results)
  File "/home/nr4325/Desktop/Pose4/mmpose/mmpose/datasets/transforms/loading.py", line 54, in transform
    results = super().transform(results)
  File "/home/nr4325/miniconda3/envs/pose4/lib/python3.8/site-packages/mmcv/transforms/loading.py", line 107, in transform
    raise e
  File "/home/nr4325/miniconda3/envs/pose4/lib/python3.8/site-packages/mmcv/transforms/loading.py", line 99, in transform
    img_bytes = fileio.get(
  File "/home/nr4325/miniconda3/envs/pose4/lib/python3.8/site-packages/mmengine/fileio/io.py", line 181, in get
    return backend.get(filepath)
  File "/home/nr4325/miniconda3/envs/pose4/lib/python3.8/site-packages/mmengine/fileio/backends/local_backend.py", line 33, in get
    with open(filepath, 'rb') as f:
FileNotFoundError: [Errno 2] No such file or directory: 'data/coco/val2017/000000138639.jpg'

: 
Caught FileNotFoundError in DataLoader worker process 1.
Original Traceback (most recent call last):
  File "/home/nr4325/miniconda3/envs/pose4/lib/python3.8/site-packages/torch/utils/data/_utils/worker.py", line 287, in _worker_loop
    data = fetcher.fetch(index)
  File "/home/nr4325/miniconda3/envs/pose4/lib/python3.8/site-packages/torch/utils/data/_utils/fetch.py", line 49, in fetch
    data = [self.dataset[idx] for idx in possibly_batched_index]
  File "/home/nr4325/miniconda3/envs/pose4/lib/python3.8/site-packages/torch/utils/data/_utils/fetch.py", line 49, in <listcomp>
    data = [self.dataset[idx] for idx in possibly_batched_index]
  File "/home/nr4325/miniconda3/envs/pose4/lib/python3.8/site-packages/mmengine/dataset/base_dataset.py", line 401, in __getitem__
    data = self.prepare_data(idx)
  File "/home/nr4325/miniconda3/envs/pose4/lib/python3.8/site-packages/mmengine/dataset/base_dataset.py", line 113, in wrapper
    return old_func(obj, *args, **kwargs)
  File "/home/nr4325/Desktop/Pose4/mmpose/mmpose/datasets/datasets/base/base_coco_style_dataset.py", line 150, in prepare_data
    return self.pipeline(data_info)
  File "/home/nr4325/miniconda3/envs/pose4/lib/python3.8/site-packages/mmengine/dataset/base_dataset.py", line 58, in __call__
    data = t(data)
  File "/home/nr4325/miniconda3/envs/pose4/lib/python3.8/site-packages/mmcv/transforms/base.py", line 12, in __call__
    return self.transform(results)
  File "/home/nr4325/Desktop/Pose4/mmpose/mmpose/datasets/transforms/loading.py", line 54, in transform
    results = super().transform(results)
  File "/home/nr4325/miniconda3/envs/pose4/lib/python3.8/site-packages/mmcv/transforms/loading.py", line 107, in transform
    raise e
  File "/home/nr4325/miniconda3/envs/pose4/lib/python3.8/site-packages/mmcv/transforms/loading.py", line 99, in transform
    img_bytes = fileio.get(
  File "/home/nr4325/miniconda3/envs/pose4/lib/python3.8/site-packages/mmengine/fileio/io.py", line 181, in get
    return backend.get(filepath)
  File "/home/nr4325/miniconda3/envs/pose4/lib/python3.8/site-packages/mmengine/fileio/backends/local_backend.py", line 33, in get
    with open(filepath, 'rb') as f:
FileNotFoundError: [Errno 2] No such file or directory: 'data/coco/val2017/000000138639.jpg'

/home/nr4325/miniconda3/envs/pose4/lib/python3.8/site-packages/torch/distributed/launch.py:178: FutureWarning: The module torch.distributed.launch is deprecated
and will be removed in future. Use torchrun.
Note that --use_env is set by default in torchrun.
If your script expects `--local_rank` argument to be set, please
change it to read from `os.environ['LOCAL_RANK']` instead. See 
https://pytorch.org/docs/stable/distributed.html#launch-utility for 
further instructions

  warnings.warn(
ERROR:torch.distributed.elastic.multiprocessing.api:failed (exitcode: 1) local_rank: 0 (pid: 393438) of binary: /home/nr4325/miniconda3/envs/pose4/bin/python
Traceback (most recent call last):
  File "/home/nr4325/miniconda3/envs/pose4/lib/python3.8/runpy.py", line 194, in _run_module_as_main
    return _run_code(code, main_globals, None,
  File "/home/nr4325/miniconda3/envs/pose4/lib/python3.8/runpy.py", line 87, in _run_code
    exec(code, run_globals)
  File "/home/nr4325/miniconda3/envs/pose4/lib/python3.8/site-packages/torch/distributed/launch.py", line 193, in <module>
    main()
  File "/home/nr4325/miniconda3/envs/pose4/lib/python3.8/site-packages/torch/distributed/launch.py", line 189, in main
    launch(args)
  File "/home/nr4325/miniconda3/envs/pose4/lib/python3.8/site-packages/torch/distributed/launch.py", line 174, in launch
    run(args)
  File "/home/nr4325/miniconda3/envs/pose4/lib/python3.8/site-packages/torch/distributed/run.py", line 715, in run
    elastic_launch(
  File "/home/nr4325/miniconda3/envs/pose4/lib/python3.8/site-packages/torch/distributed/launcher/api.py", line 131, in __call__
    return launch_agent(self._config, self._entrypoint, list(args))
  File "/home/nr4325/miniconda3/envs/pose4/lib/python3.8/site-packages/torch/distributed/launcher/api.py", line 245, in launch_agent
    raise ChildFailedError(
torch.distributed.elastic.multiprocessing.errors.ChildFailedError: 
============================================================
tools/train.py FAILED
------------------------------------------------------------
Failures:
[1]:
  time      : 2025-01-14_16:47:26
  host      : skl-a-49.rc.rit.edu
  rank      : 1 (local_rank: 1)
  exitcode  : 1 (pid: 393439)
  error_file: <N/A>
  traceback : To enable traceback see: https://pytorch.org/docs/stable/elastic/errors.html
[2]:
  time      : 2025-01-14_16:47:26
  host      : skl-a-49.rc.rit.edu
  rank      : 2 (local_rank: 2)
  exitcode  : 1 (pid: 393440)
  error_file: <N/A>
  traceback : To enable traceback see: https://pytorch.org/docs/stable/elastic/errors.html
[3]:
  time      : 2025-01-14_16:47:26
  host      : skl-a-49.rc.rit.edu
  rank      : 3 (local_rank: 3)
  exitcode  : 1 (pid: 393441)
  error_file: <N/A>
  traceback : To enable traceback see: https://pytorch.org/docs/stable/elastic/errors.html
------------------------------------------------------------
Root Cause (first observed failure):
[0]:
  time      : 2025-01-14_16:47:26
  host      : skl-a-49.rc.rit.edu
  rank      : 0 (local_rank: 0)
  exitcode  : 1 (pid: 393438)
  error_file: <N/A>
  traceback : To enable traceback see: https://pytorch.org/docs/stable/elastic/errors.html
============================================================
